[2024-11-15T10:27:18.100+0000] {local_task_job_runner.py:123} INFO - ::group::Pre task execution logs
[2024-11-15T10:27:18.112+0000] {taskinstance.py:2613} INFO - Dependencies all met for dep_context=non-requeueable deps ti=<TaskInstance: football_data.transform_data manual__2024-11-15T10:27:09.482631+00:00 [queued]>
[2024-11-15T10:27:18.118+0000] {taskinstance.py:2613} INFO - Dependencies all met for dep_context=requeueable deps ti=<TaskInstance: football_data.transform_data manual__2024-11-15T10:27:09.482631+00:00 [queued]>
[2024-11-15T10:27:18.119+0000] {taskinstance.py:2866} INFO - Starting attempt 1 of 1
[2024-11-15T10:27:18.134+0000] {taskinstance.py:2889} INFO - Executing <Task(PythonOperator): transform_data> on 2024-11-15 10:27:09.482631+00:00
[2024-11-15T10:27:18.142+0000] {standard_task_runner.py:72} INFO - Started process 6208 to run task
[2024-11-15T10:27:18.147+0000] {standard_task_runner.py:104} INFO - Running: ['airflow', 'tasks', 'run', 'football_data', 'transform_data', 'manual__2024-11-15T10:27:09.482631+00:00', '--job-id', '63', '--raw', '--subdir', 'DAGS_FOLDER/football_dag.py', '--cfg-path', '/tmp/tmpok1_phep']
[2024-11-15T10:27:18.149+0000] {standard_task_runner.py:105} INFO - Job 63: Subtask transform_data
[2024-11-15T10:27:18.196+0000] {task_command.py:467} INFO - Running <TaskInstance: football_data.transform_data manual__2024-11-15T10:27:09.482631+00:00 [running]> on host ip-172-31-28-221.eu-north-1.compute.internal
[2024-11-15T10:27:18.304+0000] {taskinstance.py:3132} INFO - Exporting env vars: AIRFLOW_CTX_DAG_OWNER='aman Singh' AIRFLOW_CTX_DAG_ID='football_data' AIRFLOW_CTX_TASK_ID='transform_data' AIRFLOW_CTX_EXECUTION_DATE='2024-11-15T10:27:09.482631+00:00' AIRFLOW_CTX_TRY_NUMBER='1' AIRFLOW_CTX_DAG_RUN_ID='manual__2024-11-15T10:27:09.482631+00:00'
[2024-11-15T10:27:18.306+0000] {taskinstance.py:731} INFO - ::endgroup::
[2024-11-15T10:27:18.335+0000] {taskinstance.py:3311} ERROR - Task failed with exception
Traceback (most recent call last):
  File "/home/ubuntu/airflow-venv/lib/python3.12/site-packages/airflow/models/taskinstance.py", line 767, in _execute_task
    result = _execute_callable(context=context, **execute_callable_kwargs)
             ^^^^^^^^^^^^^^^^^^^^^^^^^^^^^^^^^^^^^^^^^^^^^^^^^^^^^^^^^^^^^
  File "/home/ubuntu/airflow-venv/lib/python3.12/site-packages/airflow/models/taskinstance.py", line 733, in _execute_callable
    return ExecutionCallableRunner(
           ^^^^^^^^^^^^^^^^^^^^^^^^
  File "/home/ubuntu/airflow-venv/lib/python3.12/site-packages/airflow/utils/operator_helpers.py", line 252, in run
    return self.func(*args, **kwargs)
           ^^^^^^^^^^^^^^^^^^^^^^^^^^
  File "/home/ubuntu/airflow-venv/lib/python3.12/site-packages/airflow/models/baseoperator.py", line 417, in wrapper
    return func(self, *args, **kwargs)
           ^^^^^^^^^^^^^^^^^^^^^^^^^^^
  File "/home/ubuntu/airflow-venv/lib/python3.12/site-packages/airflow/operators/python.py", line 238, in execute
    return_value = self.execute_callable()
                   ^^^^^^^^^^^^^^^^^^^^^^^
  File "/home/ubuntu/airflow-venv/lib/python3.12/site-packages/airflow/operators/python.py", line 256, in execute_callable
    return runner.run(*self.op_args, **self.op_kwargs)
           ^^^^^^^^^^^^^^^^^^^^^^^^^^^^^^^^^^^^^^^^^^^
  File "/home/ubuntu/airflow-venv/lib/python3.12/site-packages/airflow/utils/operator_helpers.py", line 252, in run
    return self.func(*args, **kwargs)
           ^^^^^^^^^^^^^^^^^^^^^^^^^^
  File "/home/ubuntu/airflow/pipelines/extraction_data.py", line 79, in transform_data
    stadium_df['location'] = stadium_df.apply(lambda x: get_lat_long(x['country'],x['stadium']),axis=1)
                             ^^^^^^^^^^
UnboundLocalError: cannot access local variable 'stadium_df' where it is not associated with a value
[2024-11-15T10:27:18.341+0000] {taskinstance.py:1225} INFO - Marking task as FAILED. dag_id=football_data, task_id=transform_data, run_id=manual__2024-11-15T10:27:09.482631+00:00, execution_date=20241115T102709, start_date=20241115T102718, end_date=20241115T102718
[2024-11-15T10:27:18.355+0000] {taskinstance.py:340} INFO - ::group::Post task execution logs
[2024-11-15T10:27:18.355+0000] {standard_task_runner.py:124} ERROR - Failed to execute job 63 for task transform_data (cannot access local variable 'stadium_df' where it is not associated with a value; 6208)
Traceback (most recent call last):
  File "/home/ubuntu/airflow-venv/lib/python3.12/site-packages/airflow/task/task_runner/standard_task_runner.py", line 117, in _start_by_fork
    ret = args.func(args, dag=self.dag)
          ^^^^^^^^^^^^^^^^^^^^^^^^^^^^^
  File "/home/ubuntu/airflow-venv/lib/python3.12/site-packages/airflow/cli/cli_config.py", line 49, in command
    return func(*args, **kwargs)
           ^^^^^^^^^^^^^^^^^^^^^
  File "/home/ubuntu/airflow-venv/lib/python3.12/site-packages/airflow/utils/cli.py", line 116, in wrapper
    return f(*args, **kwargs)
           ^^^^^^^^^^^^^^^^^^
  File "/home/ubuntu/airflow-venv/lib/python3.12/site-packages/airflow/cli/commands/task_command.py", line 483, in task_run
    task_return_code = _run_task_by_selected_method(args, _dag, ti)
                       ^^^^^^^^^^^^^^^^^^^^^^^^^^^^^^^^^^^^^^^^^^^^
  File "/home/ubuntu/airflow-venv/lib/python3.12/site-packages/airflow/cli/commands/task_command.py", line 256, in _run_task_by_selected_method
    return _run_raw_task(args, ti)
           ^^^^^^^^^^^^^^^^^^^^^^^
  File "/home/ubuntu/airflow-venv/lib/python3.12/site-packages/airflow/cli/commands/task_command.py", line 341, in _run_raw_task
    return ti._run_raw_task(
           ^^^^^^^^^^^^^^^^^
  File "/home/ubuntu/airflow-venv/lib/python3.12/site-packages/airflow/utils/session.py", line 97, in wrapper
    return func(*args, session=session, **kwargs)
           ^^^^^^^^^^^^^^^^^^^^^^^^^^^^^^^^^^^^^^
  File "/home/ubuntu/airflow-venv/lib/python3.12/site-packages/airflow/models/taskinstance.py", line 3005, in _run_raw_task
    return _run_raw_task(
           ^^^^^^^^^^^^^^
  File "/home/ubuntu/airflow-venv/lib/python3.12/site-packages/airflow/models/taskinstance.py", line 273, in _run_raw_task
    TaskInstance._execute_task_with_callbacks(
  File "/home/ubuntu/airflow-venv/lib/python3.12/site-packages/airflow/models/taskinstance.py", line 3159, in _execute_task_with_callbacks
    result = self._execute_task(context, task_orig)
             ^^^^^^^^^^^^^^^^^^^^^^^^^^^^^^^^^^^^^^
  File "/home/ubuntu/airflow-venv/lib/python3.12/site-packages/airflow/models/taskinstance.py", line 3183, in _execute_task
    return _execute_task(self, context, task_orig)
           ^^^^^^^^^^^^^^^^^^^^^^^^^^^^^^^^^^^^^^^
  File "/home/ubuntu/airflow-venv/lib/python3.12/site-packages/airflow/models/taskinstance.py", line 767, in _execute_task
    result = _execute_callable(context=context, **execute_callable_kwargs)
             ^^^^^^^^^^^^^^^^^^^^^^^^^^^^^^^^^^^^^^^^^^^^^^^^^^^^^^^^^^^^^
  File "/home/ubuntu/airflow-venv/lib/python3.12/site-packages/airflow/models/taskinstance.py", line 733, in _execute_callable
    return ExecutionCallableRunner(
           ^^^^^^^^^^^^^^^^^^^^^^^^
  File "/home/ubuntu/airflow-venv/lib/python3.12/site-packages/airflow/utils/operator_helpers.py", line 252, in run
    return self.func(*args, **kwargs)
           ^^^^^^^^^^^^^^^^^^^^^^^^^^
  File "/home/ubuntu/airflow-venv/lib/python3.12/site-packages/airflow/models/baseoperator.py", line 417, in wrapper
    return func(self, *args, **kwargs)
           ^^^^^^^^^^^^^^^^^^^^^^^^^^^
  File "/home/ubuntu/airflow-venv/lib/python3.12/site-packages/airflow/operators/python.py", line 238, in execute
    return_value = self.execute_callable()
                   ^^^^^^^^^^^^^^^^^^^^^^^
  File "/home/ubuntu/airflow-venv/lib/python3.12/site-packages/airflow/operators/python.py", line 256, in execute_callable
    return runner.run(*self.op_args, **self.op_kwargs)
           ^^^^^^^^^^^^^^^^^^^^^^^^^^^^^^^^^^^^^^^^^^^
  File "/home/ubuntu/airflow-venv/lib/python3.12/site-packages/airflow/utils/operator_helpers.py", line 252, in run
    return self.func(*args, **kwargs)
           ^^^^^^^^^^^^^^^^^^^^^^^^^^
  File "/home/ubuntu/airflow/pipelines/extraction_data.py", line 79, in transform_data
    stadium_df['location'] = stadium_df.apply(lambda x: get_lat_long(x['country'],x['stadium']),axis=1)
                             ^^^^^^^^^^
UnboundLocalError: cannot access local variable 'stadium_df' where it is not associated with a value
[2024-11-15T10:27:18.400+0000] {local_task_job_runner.py:266} INFO - Task exited with return code 1
[2024-11-15T10:27:18.413+0000] {taskinstance.py:3895} INFO - 0 downstream tasks scheduled from follow-on schedule check
[2024-11-15T10:27:18.414+0000] {local_task_job_runner.py:245} INFO - ::endgroup::
